python: can't open file '/root/SomethinK/tun.py': [Errno 2] No such file or directory
/usr/local/lib/python3.9/site-packages/flask_limiter/extension.py:293: UserWarning: Using the in-memory storage for tracking rate limits as no storage was explicitly specified. This is not recommended for production use. See: https://flask-limiter.readthedocs.io#configuring-a-storage-backend for documentation about configuring the storage backend.
  warnings.warn(
Подключение к базе данных по адресу sqlite:///app/db/db.db?check_same_thread=False
 * Serving Flask app 'app'
 * Debug mode: on
WARNING: This is a development server. Do not use it in a production deployment. Use a production WSGI server instead.
 * Running on http://94.198.216.152:80
Press CTRL+C to quit
Updates were skipped successfully.
/usr/local/lib/python3.9/site-packages/flask_limiter/extension.py:293: UserWarning: Using the in-memory storage for tracking rate limits as no storage was explicitly specified. This is not recommended for production use. See: https://flask-limiter.readthedocs.io#configuring-a-storage-backend for documentation about configuring the storage backend.
  warnings.warn(
Подключение к базе данных по адресу sqlite:///app/db/db.db?check_same_thread=False
 * Serving Flask app 'app'
 * Debug mode: on
Address already in use
Port 80 is in use by another program. Either identify and stop that program, or start the server with a different port.
Updates were skipped successfully.
Cause exception while getting updates.
Traceback (most recent call last):
  File "/usr/local/lib/python3.9/site-packages/aiogram/dispatcher/dispatcher.py", line 381, in start_polling
    updates = await self.bot.get_updates(
  File "/usr/local/lib/python3.9/site-packages/aiogram/bot/bot.py", line 110, in get_updates
    result = await self.request(api.Methods.GET_UPDATES, payload)
  File "/usr/local/lib/python3.9/site-packages/aiogram/bot/base.py", line 236, in request
    return await api.make_request(await self.get_session(), self.server, self.__token, method, data, files,
  File "/usr/local/lib/python3.9/site-packages/aiogram/bot/api.py", line 140, in make_request
    return check_result(method, response.content_type, response.status, await response.text())
  File "/usr/local/lib/python3.9/site-packages/aiogram/bot/api.py", line 119, in check_result
    exceptions.ConflictError.detect(description)
  File "/usr/local/lib/python3.9/site-packages/aiogram/utils/exceptions.py", line 140, in detect
    raise err(cls.text or description)
aiogram.utils.exceptions.TerminatedByOtherGetUpdates: Terminated by other getupdates request; make sure that only one bot instance is running
Cause exception while getting updates.
Traceback (most recent call last):
  File "/usr/local/lib/python3.9/site-packages/aiogram/dispatcher/dispatcher.py", line 381, in start_polling
    updates = await self.bot.get_updates(
  File "/usr/local/lib/python3.9/site-packages/aiogram/bot/bot.py", line 110, in get_updates
    result = await self.request(api.Methods.GET_UPDATES, payload)
  File "/usr/local/lib/python3.9/site-packages/aiogram/bot/base.py", line 236, in request
    return await api.make_request(await self.get_session(), self.server, self.__token, method, data, files,
  File "/usr/local/lib/python3.9/site-packages/aiogram/bot/api.py", line 140, in make_request
    return check_result(method, response.content_type, response.status, await response.text())
  File "/usr/local/lib/python3.9/site-packages/aiogram/bot/api.py", line 119, in check_result
    exceptions.ConflictError.detect(description)
  File "/usr/local/lib/python3.9/site-packages/aiogram/utils/exceptions.py", line 140, in detect
    raise err(cls.text or description)
aiogram.utils.exceptions.TerminatedByOtherGetUpdates: Terminated by other getupdates request; make sure that only one bot instance is running
Goodbye!
Exception ignored in: <module 'threading' from '/usr/lib64/python3.9/threading.py'>
Traceback (most recent call last):
  File "/usr/lib64/python3.9/threading.py", line 1477, in _shutdown
    lock.acquire()
KeyboardInterrupt: 
Cause exception while getting updates.
Traceback (most recent call last):
  File "/usr/local/lib/python3.9/site-packages/aiogram/dispatcher/dispatcher.py", line 381, in start_polling
    updates = await self.bot.get_updates(
  File "/usr/local/lib/python3.9/site-packages/aiogram/bot/bot.py", line 110, in get_updates
    result = await self.request(api.Methods.GET_UPDATES, payload)
  File "/usr/local/lib/python3.9/site-packages/aiogram/bot/base.py", line 236, in request
    return await api.make_request(await self.get_session(), self.server, self.__token, method, data, files,
  File "/usr/local/lib/python3.9/site-packages/aiogram/bot/api.py", line 140, in make_request
    return check_result(method, response.content_type, response.status, await response.text())
  File "/usr/local/lib/python3.9/site-packages/aiogram/bot/api.py", line 119, in check_result
    exceptions.ConflictError.detect(description)
  File "/usr/local/lib/python3.9/site-packages/aiogram/utils/exceptions.py", line 140, in detect
    raise err(cls.text or description)
aiogram.utils.exceptions.TerminatedByOtherGetUpdates: Terminated by other getupdates request; make sure that only one bot instance is running
Cause exception while getting updates.
Traceback (most recent call last):
  File "/usr/local/lib/python3.9/site-packages/aiogram/dispatcher/dispatcher.py", line 381, in start_polling
    updates = await self.bot.get_updates(
  File "/usr/local/lib/python3.9/site-packages/aiogram/bot/bot.py", line 110, in get_updates
    result = await self.request(api.Methods.GET_UPDATES, payload)
  File "/usr/local/lib/python3.9/site-packages/aiogram/bot/base.py", line 236, in request
    return await api.make_request(await self.get_session(), self.server, self.__token, method, data, files,
  File "/usr/local/lib/python3.9/site-packages/aiogram/bot/api.py", line 140, in make_request
    return check_result(method, response.content_type, response.status, await response.text())
  File "/usr/local/lib/python3.9/site-packages/aiogram/bot/api.py", line 119, in check_result
    exceptions.ConflictError.detect(description)
  File "/usr/local/lib/python3.9/site-packages/aiogram/utils/exceptions.py", line 140, in detect
    raise err(cls.text or description)
aiogram.utils.exceptions.TerminatedByOtherGetUpdates: Terminated by other getupdates request; make sure that only one bot instance is running
92.43.167.54 - - [07/Aug/2023 12:54:51] "GET / HTTP/1.1" 200 -
92.43.167.54 - - [07/Aug/2023 12:54:52] "GET /static/css/main/main.css HTTP/1.1" 304 -
92.43.167.54 - - [07/Aug/2023 12:54:52] "GET /static/css/main/index.css HTTP/1.1" 304 -
92.43.167.54 - - [07/Aug/2023 12:54:52] "GET /static/img/icon_twitch.svg HTTP/1.1" 200 -
92.43.167.54 - - [07/Aug/2023 12:54:52] "GET /static/img/icon_moder.svg HTTP/1.1" 200 -
92.43.167.54 - - [07/Aug/2023 12:54:52] "GET /static/img/icon_autorole.svg HTTP/1.1" 200 -
92.43.167.54 - - [07/Aug/2023 12:54:52] "GET /static/img/icon_automod.svg HTTP/1.1" 200 -
92.43.167.54 - - [07/Aug/2023 12:54:52] "GET /static/img/icon_youtube.svg HTTP/1.1" 200 -
92.43.167.54 - - [07/Aug/2023 12:54:52] "GET /static/img/icon_messages.svg HTTP/1.1" 200 -
92.43.167.54 - - [07/Aug/2023 12:54:52] "GET /static/img/icon_translate.svg HTTP/1.1" 200 -
92.43.167.54 - - [07/Aug/2023 12:54:52] "GET /static/img/icon_joke.svg HTTP/1.1" 200 -
92.43.167.54 - - [07/Aug/2023 12:54:52] "GET /static/img/icon_color.svg HTTP/1.1" 200 -
92.43.167.54 - - [07/Aug/2023 12:54:52] "GET /static/img/icon_gpt.svg HTTP/1.1" 304 -
92.43.167.54 - - [07/Aug/2023 12:54:52] "GET /static/fonts/itim-cyrillic.otf HTTP/1.1" 304 -
Cause exception while getting updates.
Traceback (most recent call last):
  File "/usr/local/lib/python3.9/site-packages/aiogram/dispatcher/dispatcher.py", line 381, in start_polling
    updates = await self.bot.get_updates(
  File "/usr/local/lib/python3.9/site-packages/aiogram/bot/bot.py", line 110, in get_updates
    result = await self.request(api.Methods.GET_UPDATES, payload)
  File "/usr/local/lib/python3.9/site-packages/aiogram/bot/base.py", line 236, in request
    return await api.make_request(await self.get_session(), self.server, self.__token, method, data, files,
  File "/usr/local/lib/python3.9/site-packages/aiogram/bot/api.py", line 140, in make_request
    return check_result(method, response.content_type, response.status, await response.text())
  File "/usr/local/lib/python3.9/site-packages/aiogram/bot/api.py", line 119, in check_result
    exceptions.ConflictError.detect(description)
  File "/usr/local/lib/python3.9/site-packages/aiogram/utils/exceptions.py", line 140, in detect
    raise err(cls.text or description)
aiogram.utils.exceptions.TerminatedByOtherGetUpdates: Terminated by other getupdates request; make sure that only one bot instance is running
Cause exception while getting updates.
Traceback (most recent call last):
  File "/usr/local/lib/python3.9/site-packages/aiogram/dispatcher/dispatcher.py", line 381, in start_polling
    updates = await self.bot.get_updates(
  File "/usr/local/lib/python3.9/site-packages/aiogram/bot/bot.py", line 110, in get_updates
    result = await self.request(api.Methods.GET_UPDATES, payload)
  File "/usr/local/lib/python3.9/site-packages/aiogram/bot/base.py", line 236, in request
    return await api.make_request(await self.get_session(), self.server, self.__token, method, data, files,
  File "/usr/local/lib/python3.9/site-packages/aiogram/bot/api.py", line 140, in make_request
    return check_result(method, response.content_type, response.status, await response.text())
  File "/usr/local/lib/python3.9/site-packages/aiogram/bot/api.py", line 119, in check_result
    exceptions.ConflictError.detect(description)
  File "/usr/local/lib/python3.9/site-packages/aiogram/utils/exceptions.py", line 140, in detect
    raise err(cls.text or description)
aiogram.utils.exceptions.TerminatedByOtherGetUpdates: Terminated by other getupdates request; make sure that only one bot instance is running
92.43.167.54 - - [07/Aug/2023 12:55:16] "GET / HTTP/1.1" 200 -
92.43.167.54 - - [07/Aug/2023 12:55:16] "GET /static/css/main/main.css HTTP/1.1" 304 -
92.43.167.54 - - [07/Aug/2023 12:55:16] "GET /static/css/main/index.css HTTP/1.1" 304 -
92.43.167.54 - - [07/Aug/2023 12:55:16] "GET /static/img/icon_youtube.svg HTTP/1.1" 304 -
92.43.167.54 - - [07/Aug/2023 12:55:16] "GET /static/img/icon_messages.svg HTTP/1.1" 304 -
92.43.167.54 - - [07/Aug/2023 12:55:16] "GET /static/img/icon_autorole.svg HTTP/1.1" 304 -
92.43.167.54 - - [07/Aug/2023 12:55:16] "GET /static/img/icon_twitch.svg HTTP/1.1" 304 -
92.43.167.54 - - [07/Aug/2023 12:55:16] "GET /static/img/icon_automod.svg HTTP/1.1" 304 -
92.43.167.54 - - [07/Aug/2023 12:55:16] "GET /static/img/icon_moder.svg HTTP/1.1" 304 -
92.43.167.54 - - [07/Aug/2023 12:55:16] "GET /static/img/icon_gpt.svg HTTP/1.1" 304 -
92.43.167.54 - - [07/Aug/2023 12:55:16] "GET /static/img/icon_translate.svg HTTP/1.1" 304 -
92.43.167.54 - - [07/Aug/2023 12:55:16] "GET /static/img/icon_joke.svg HTTP/1.1" 304 -
92.43.167.54 - - [07/Aug/2023 12:55:16] "GET /static/img/icon_color.svg HTTP/1.1" 304 -
92.43.167.54 - - [07/Aug/2023 12:55:20] "GET / HTTP/1.1" 200 -
92.43.167.54 - - [07/Aug/2023 12:55:20] "GET /static/css/main/index.css HTTP/1.1" 304 -
92.43.167.54 - - [07/Aug/2023 12:55:20] "GET /static/css/main/main.css HTTP/1.1" 304 -
92.43.167.54 - - [07/Aug/2023 12:55:20] "GET /static/img/icon_autorole.svg HTTP/1.1" 304 -
92.43.167.54 - - [07/Aug/2023 12:55:20] "GET /static/img/icon_automod.svg HTTP/1.1" 304 -
92.43.167.54 - - [07/Aug/2023 12:55:20] "GET /static/img/icon_color.svg HTTP/1.1" 304 -
92.43.167.54 - - [07/Aug/2023 12:55:20] "GET /static/img/icon_joke.svg HTTP/1.1" 304 -
92.43.167.54 - - [07/Aug/2023 12:55:20] "GET /static/img/icon_moder.svg HTTP/1.1" 304 -
92.43.167.54 - - [07/Aug/2023 12:55:20] "GET /static/img/icon_messages.svg HTTP/1.1" 304 -
92.43.167.54 - - [07/Aug/2023 12:55:20] "GET /static/img/icon_translate.svg HTTP/1.1" 304 -
92.43.167.54 - - [07/Aug/2023 12:55:20] "GET /static/img/icon_youtube.svg HTTP/1.1" 304 -
92.43.167.54 - - [07/Aug/2023 12:55:20] "GET /static/img/icon_gpt.svg HTTP/1.1" 304 -
92.43.167.54 - - [07/Aug/2023 12:55:20] "GET /static/img/icon_twitch.svg HTTP/1.1" 304 -
Cause exception while getting updates.
Traceback (most recent call last):
  File "/usr/local/lib/python3.9/site-packages/aiogram/dispatcher/dispatcher.py", line 381, in start_polling
    updates = await self.bot.get_updates(
  File "/usr/local/lib/python3.9/site-packages/aiogram/bot/bot.py", line 110, in get_updates
    result = await self.request(api.Methods.GET_UPDATES, payload)
  File "/usr/local/lib/python3.9/site-packages/aiogram/bot/base.py", line 236, in request
    return await api.make_request(await self.get_session(), self.server, self.__token, method, data, files,
  File "/usr/local/lib/python3.9/site-packages/aiogram/bot/api.py", line 140, in make_request
    return check_result(method, response.content_type, response.status, await response.text())
  File "/usr/local/lib/python3.9/site-packages/aiogram/bot/api.py", line 119, in check_result
    exceptions.ConflictError.detect(description)
  File "/usr/local/lib/python3.9/site-packages/aiogram/utils/exceptions.py", line 140, in detect
    raise err(cls.text or description)
aiogram.utils.exceptions.TerminatedByOtherGetUpdates: Terminated by other getupdates request; make sure that only one bot instance is running
Cause exception while getting updates.
Traceback (most recent call last):
  File "/usr/local/lib/python3.9/site-packages/aiogram/dispatcher/dispatcher.py", line 381, in start_polling
    updates = await self.bot.get_updates(
  File "/usr/local/lib/python3.9/site-packages/aiogram/bot/bot.py", line 110, in get_updates
    result = await self.request(api.Methods.GET_UPDATES, payload)
  File "/usr/local/lib/python3.9/site-packages/aiogram/bot/base.py", line 236, in request
    return await api.make_request(await self.get_session(), self.server, self.__token, method, data, files,
  File "/usr/local/lib/python3.9/site-packages/aiogram/bot/api.py", line 140, in make_request
    return check_result(method, response.content_type, response.status, await response.text())
  File "/usr/local/lib/python3.9/site-packages/aiogram/bot/api.py", line 119, in check_result
    exceptions.ConflictError.detect(description)
  File "/usr/local/lib/python3.9/site-packages/aiogram/utils/exceptions.py", line 140, in detect
    raise err(cls.text or description)
aiogram.utils.exceptions.TerminatedByOtherGetUpdates: Terminated by other getupdates request; make sure that only one bot instance is running
92.43.167.54 - - [07/Aug/2023 12:55:33] "GET / HTTP/1.1" 200 -
92.43.167.54 - - [07/Aug/2023 12:55:34] "GET /static/css/main/main.css HTTP/1.1" 304 -
92.43.167.54 - - [07/Aug/2023 12:55:34] "GET /static/css/main/index.css HTTP/1.1" 304 -
92.43.167.54 - - [07/Aug/2023 12:55:34] "GET /static/img/icon_moder.svg HTTP/1.1" 304 -
92.43.167.54 - - [07/Aug/2023 12:55:34] "GET /static/img/icon_messages.svg HTTP/1.1" 304 -
92.43.167.54 - - [07/Aug/2023 12:55:34] "GET /static/img/icon_autorole.svg HTTP/1.1" 304 -
92.43.167.54 - - [07/Aug/2023 12:55:34] "GET /static/img/icon_color.svg HTTP/1.1" 304 -
92.43.167.54 - - [07/Aug/2023 12:55:34] "GET /static/img/icon_automod.svg HTTP/1.1" 304 -
92.43.167.54 - - [07/Aug/2023 12:55:34] "GET /static/img/icon_joke.svg HTTP/1.1" 304 -
92.43.167.54 - - [07/Aug/2023 12:55:34] "GET /static/img/icon_translate.svg HTTP/1.1" 304 -
92.43.167.54 - - [07/Aug/2023 12:55:34] "GET /static/img/icon_youtube.svg HTTP/1.1" 304 -
92.43.167.54 - - [07/Aug/2023 12:55:34] "GET /static/img/icon_twitch.svg HTTP/1.1" 304 -
92.43.167.54 - - [07/Aug/2023 12:55:34] "GET /static/img/icon_gpt.svg HTTP/1.1" 304 -
Cause exception while getting updates.
Traceback (most recent call last):
  File "/usr/local/lib/python3.9/site-packages/aiogram/dispatcher/dispatcher.py", line 381, in start_polling
    updates = await self.bot.get_updates(
  File "/usr/local/lib/python3.9/site-packages/aiogram/bot/bot.py", line 110, in get_updates
    result = await self.request(api.Methods.GET_UPDATES, payload)
  File "/usr/local/lib/python3.9/site-packages/aiogram/bot/base.py", line 236, in request
    return await api.make_request(await self.get_session(), self.server, self.__token, method, data, files,
  File "/usr/local/lib/python3.9/site-packages/aiogram/bot/api.py", line 140, in make_request
    return check_result(method, response.content_type, response.status, await response.text())
  File "/usr/local/lib/python3.9/site-packages/aiogram/bot/api.py", line 119, in check_result
    exceptions.ConflictError.detect(description)
  File "/usr/local/lib/python3.9/site-packages/aiogram/utils/exceptions.py", line 140, in detect
    raise err(cls.text or description)
aiogram.utils.exceptions.TerminatedByOtherGetUpdates: Terminated by other getupdates request; make sure that only one bot instance is running
Cause exception while getting updates.
Traceback (most recent call last):
  File "/usr/local/lib/python3.9/site-packages/aiogram/dispatcher/dispatcher.py", line 381, in start_polling
    updates = await self.bot.get_updates(
  File "/usr/local/lib/python3.9/site-packages/aiogram/bot/bot.py", line 110, in get_updates
    result = await self.request(api.Methods.GET_UPDATES, payload)
  File "/usr/local/lib/python3.9/site-packages/aiogram/bot/base.py", line 236, in request
    return await api.make_request(await self.get_session(), self.server, self.__token, method, data, files,
  File "/usr/local/lib/python3.9/site-packages/aiogram/bot/api.py", line 140, in make_request
    return check_result(method, response.content_type, response.status, await response.text())
  File "/usr/local/lib/python3.9/site-packages/aiogram/bot/api.py", line 119, in check_result
    exceptions.ConflictError.detect(description)
  File "/usr/local/lib/python3.9/site-packages/aiogram/utils/exceptions.py", line 140, in detect
    raise err(cls.text or description)
aiogram.utils.exceptions.TerminatedByOtherGetUpdates: Terminated by other getupdates request; make sure that only one bot instance is running
Cause exception while getting updates.
Traceback (most recent call last):
  File "/usr/local/lib/python3.9/site-packages/aiogram/dispatcher/dispatcher.py", line 381, in start_polling
    updates = await self.bot.get_updates(
  File "/usr/local/lib/python3.9/site-packages/aiogram/bot/bot.py", line 110, in get_updates
    result = await self.request(api.Methods.GET_UPDATES, payload)
  File "/usr/local/lib/python3.9/site-packages/aiogram/bot/base.py", line 236, in request
    return await api.make_request(await self.get_session(), self.server, self.__token, method, data, files,
  File "/usr/local/lib/python3.9/site-packages/aiogram/bot/api.py", line 140, in make_request
    return check_result(method, response.content_type, response.status, await response.text())
  File "/usr/local/lib/python3.9/site-packages/aiogram/bot/api.py", line 119, in check_result
    exceptions.ConflictError.detect(description)
  File "/usr/local/lib/python3.9/site-packages/aiogram/utils/exceptions.py", line 140, in detect
    raise err(cls.text or description)
aiogram.utils.exceptions.TerminatedByOtherGetUpdates: Terminated by other getupdates request; make sure that only one bot instance is running
Cause exception while getting updates.
Traceback (most recent call last):
  File "/usr/local/lib/python3.9/site-packages/aiogram/dispatcher/dispatcher.py", line 381, in start_polling
    updates = await self.bot.get_updates(
  File "/usr/local/lib/python3.9/site-packages/aiogram/bot/bot.py", line 110, in get_updates
    result = await self.request(api.Methods.GET_UPDATES, payload)
  File "/usr/local/lib/python3.9/site-packages/aiogram/bot/base.py", line 236, in request
    return await api.make_request(await self.get_session(), self.server, self.__token, method, data, files,
  File "/usr/local/lib/python3.9/site-packages/aiogram/bot/api.py", line 140, in make_request
    return check_result(method, response.content_type, response.status, await response.text())
  File "/usr/local/lib/python3.9/site-packages/aiogram/bot/api.py", line 119, in check_result
    exceptions.ConflictError.detect(description)
  File "/usr/local/lib/python3.9/site-packages/aiogram/utils/exceptions.py", line 140, in detect
    raise err(cls.text or description)
aiogram.utils.exceptions.TerminatedByOtherGetUpdates: Terminated by other getupdates request; make sure that only one bot instance is running
Cause exception while getting updates.
Traceback (most recent call last):
  File "/usr/local/lib/python3.9/site-packages/aiogram/dispatcher/dispatcher.py", line 381, in start_polling
    updates = await self.bot.get_updates(
  File "/usr/local/lib/python3.9/site-packages/aiogram/bot/bot.py", line 110, in get_updates
    result = await self.request(api.Methods.GET_UPDATES, payload)
  File "/usr/local/lib/python3.9/site-packages/aiogram/bot/base.py", line 236, in request
    return await api.make_request(await self.get_session(), self.server, self.__token, method, data, files,
  File "/usr/local/lib/python3.9/site-packages/aiogram/bot/api.py", line 140, in make_request
    return check_result(method, response.content_type, response.status, await response.text())
  File "/usr/local/lib/python3.9/site-packages/aiogram/bot/api.py", line 119, in check_result
    exceptions.ConflictError.detect(description)
  File "/usr/local/lib/python3.9/site-packages/aiogram/utils/exceptions.py", line 140, in detect
    raise err(cls.text or description)
aiogram.utils.exceptions.TerminatedByOtherGetUpdates: Terminated by other getupdates request; make sure that only one bot instance is running
92.43.167.54 - - [07/Aug/2023 12:56:30] "GET / HTTP/1.1" 200 -
92.43.167.54 - - [07/Aug/2023 12:56:30] "GET /static/css/main/main.css HTTP/1.1" 304 -
92.43.167.54 - - [07/Aug/2023 12:56:30] "GET /static/css/main/index.css HTTP/1.1" 304 -
92.43.167.54 - - [07/Aug/2023 12:56:30] "GET /static/img/icon_moder.svg HTTP/1.1" 304 -
92.43.167.54 - - [07/Aug/2023 12:56:30] "GET /static/img/icon_messages.svg HTTP/1.1" 304 -
92.43.167.54 - - [07/Aug/2023 12:56:30] "GET /static/img/icon_autorole.svg HTTP/1.1" 304 -
92.43.167.54 - - [07/Aug/2023 12:56:30] "GET /static/img/icon_color.svg HTTP/1.1" 304 -
92.43.167.54 - - [07/Aug/2023 12:56:30] "GET /static/img/icon_joke.svg HTTP/1.1" 304 -
92.43.167.54 - - [07/Aug/2023 12:56:30] "GET /static/img/icon_automod.svg HTTP/1.1" 304 -
92.43.167.54 - - [07/Aug/2023 12:56:30] "GET /static/img/icon_translate.svg HTTP/1.1" 304 -
92.43.167.54 - - [07/Aug/2023 12:56:30] "GET /static/img/icon_gpt.svg HTTP/1.1" 304 -
92.43.167.54 - - [07/Aug/2023 12:56:30] "GET /static/img/icon_youtube.svg HTTP/1.1" 304 -
92.43.167.54 - - [07/Aug/2023 12:56:30] "GET /static/img/icon_twitch.svg HTTP/1.1" 304 -
Cause exception while getting updates.
Traceback (most recent call last):
  File "/usr/local/lib/python3.9/site-packages/aiogram/dispatcher/dispatcher.py", line 381, in start_polling
    updates = await self.bot.get_updates(
  File "/usr/local/lib/python3.9/site-packages/aiogram/bot/bot.py", line 110, in get_updates
    result = await self.request(api.Methods.GET_UPDATES, payload)
  File "/usr/local/lib/python3.9/site-packages/aiogram/bot/base.py", line 236, in request
    return await api.make_request(await self.get_session(), self.server, self.__token, method, data, files,
  File "/usr/local/lib/python3.9/site-packages/aiogram/bot/api.py", line 140, in make_request
    return check_result(method, response.content_type, response.status, await response.text())
  File "/usr/local/lib/python3.9/site-packages/aiogram/bot/api.py", line 119, in check_result
    exceptions.ConflictError.detect(description)
  File "/usr/local/lib/python3.9/site-packages/aiogram/utils/exceptions.py", line 140, in detect
    raise err(cls.text or description)
aiogram.utils.exceptions.TerminatedByOtherGetUpdates: Terminated by other getupdates request; make sure that only one bot instance is running
Cause exception while getting updates.
Traceback (most recent call last):
  File "/usr/local/lib/python3.9/site-packages/aiogram/dispatcher/dispatcher.py", line 381, in start_polling
    updates = await self.bot.get_updates(
  File "/usr/local/lib/python3.9/site-packages/aiogram/bot/bot.py", line 110, in get_updates
    result = await self.request(api.Methods.GET_UPDATES, payload)
  File "/usr/local/lib/python3.9/site-packages/aiogram/bot/base.py", line 236, in request
    return await api.make_request(await self.get_session(), self.server, self.__token, method, data, files,
  File "/usr/local/lib/python3.9/site-packages/aiogram/bot/api.py", line 140, in make_request
    return check_result(method, response.content_type, response.status, await response.text())
  File "/usr/local/lib/python3.9/site-packages/aiogram/bot/api.py", line 119, in check_result
    exceptions.ConflictError.detect(description)
  File "/usr/local/lib/python3.9/site-packages/aiogram/utils/exceptions.py", line 140, in detect
    raise err(cls.text or description)
aiogram.utils.exceptions.TerminatedByOtherGetUpdates: Terminated by other getupdates request; make sure that only one bot instance is running
Cause exception while getting updates.
Traceback (most recent call last):
  File "/usr/local/lib/python3.9/site-packages/aiogram/dispatcher/dispatcher.py", line 381, in start_polling
    updates = await self.bot.get_updates(
  File "/usr/local/lib/python3.9/site-packages/aiogram/bot/bot.py", line 110, in get_updates
    result = await self.request(api.Methods.GET_UPDATES, payload)
  File "/usr/local/lib/python3.9/site-packages/aiogram/bot/base.py", line 236, in request
    return await api.make_request(await self.get_session(), self.server, self.__token, method, data, files,
  File "/usr/local/lib/python3.9/site-packages/aiogram/bot/api.py", line 140, in make_request
    return check_result(method, response.content_type, response.status, await response.text())
  File "/usr/local/lib/python3.9/site-packages/aiogram/bot/api.py", line 119, in check_result
    exceptions.ConflictError.detect(description)
  File "/usr/local/lib/python3.9/site-packages/aiogram/utils/exceptions.py", line 140, in detect
    raise err(cls.text or description)
aiogram.utils.exceptions.TerminatedByOtherGetUpdates: Terminated by other getupdates request; make sure that only one bot instance is running
Cause exception while getting updates.
Traceback (most recent call last):
  File "/usr/local/lib/python3.9/site-packages/aiogram/dispatcher/dispatcher.py", line 381, in start_polling
    updates = await self.bot.get_updates(
  File "/usr/local/lib/python3.9/site-packages/aiogram/bot/bot.py", line 110, in get_updates
    result = await self.request(api.Methods.GET_UPDATES, payload)
  File "/usr/local/lib/python3.9/site-packages/aiogram/bot/base.py", line 236, in request
    return await api.make_request(await self.get_session(), self.server, self.__token, method, data, files,
  File "/usr/local/lib/python3.9/site-packages/aiogram/bot/api.py", line 140, in make_request
    return check_result(method, response.content_type, response.status, await response.text())
  File "/usr/local/lib/python3.9/site-packages/aiogram/bot/api.py", line 119, in check_result
    exceptions.ConflictError.detect(description)
  File "/usr/local/lib/python3.9/site-packages/aiogram/utils/exceptions.py", line 140, in detect
    raise err(cls.text or description)
aiogram.utils.exceptions.TerminatedByOtherGetUpdates: Terminated by other getupdates request; make sure that only one bot instance is running
Cause exception while getting updates.
Traceback (most recent call last):
  File "/usr/local/lib/python3.9/site-packages/aiogram/dispatcher/dispatcher.py", line 381, in start_polling
    updates = await self.bot.get_updates(
  File "/usr/local/lib/python3.9/site-packages/aiogram/bot/bot.py", line 110, in get_updates
    result = await self.request(api.Methods.GET_UPDATES, payload)
  File "/usr/local/lib/python3.9/site-packages/aiogram/bot/base.py", line 236, in request
    return await api.make_request(await self.get_session(), self.server, self.__token, method, data, files,
  File "/usr/local/lib/python3.9/site-packages/aiogram/bot/api.py", line 140, in make_request
    return check_result(method, response.content_type, response.status, await response.text())
  File "/usr/local/lib/python3.9/site-packages/aiogram/bot/api.py", line 119, in check_result
    exceptions.ConflictError.detect(description)
  File "/usr/local/lib/python3.9/site-packages/aiogram/utils/exceptions.py", line 140, in detect
    raise err(cls.text or description)
aiogram.utils.exceptions.TerminatedByOtherGetUpdates: Terminated by other getupdates request; make sure that only one bot instance is running
Cause exception while getting updates.
Traceback (most recent call last):
  File "/usr/local/lib/python3.9/site-packages/aiogram/dispatcher/dispatcher.py", line 381, in start_polling
    updates = await self.bot.get_updates(
  File "/usr/local/lib/python3.9/site-packages/aiogram/bot/bot.py", line 110, in get_updates
    result = await self.request(api.Methods.GET_UPDATES, payload)
  File "/usr/local/lib/python3.9/site-packages/aiogram/bot/base.py", line 236, in request
    return await api.make_request(await self.get_session(), self.server, self.__token, method, data, files,
  File "/usr/local/lib/python3.9/site-packages/aiogram/bot/api.py", line 140, in make_request
    return check_result(method, response.content_type, response.status, await response.text())
  File "/usr/local/lib/python3.9/site-packages/aiogram/bot/api.py", line 119, in check_result
    exceptions.ConflictError.detect(description)
  File "/usr/local/lib/python3.9/site-packages/aiogram/utils/exceptions.py", line 140, in detect
    raise err(cls.text or description)
aiogram.utils.exceptions.TerminatedByOtherGetUpdates: Terminated by other getupdates request; make sure that only one bot instance is running
Cause exception while getting updates.
Traceback (most recent call last):
  File "/usr/local/lib/python3.9/site-packages/aiogram/dispatcher/dispatcher.py", line 381, in start_polling
    updates = await self.bot.get_updates(
  File "/usr/local/lib/python3.9/site-packages/aiogram/bot/bot.py", line 110, in get_updates
    result = await self.request(api.Methods.GET_UPDATES, payload)
  File "/usr/local/lib/python3.9/site-packages/aiogram/bot/base.py", line 236, in request
    return await api.make_request(await self.get_session(), self.server, self.__token, method, data, files,
  File "/usr/local/lib/python3.9/site-packages/aiogram/bot/api.py", line 140, in make_request
    return check_result(method, response.content_type, response.status, await response.text())
  File "/usr/local/lib/python3.9/site-packages/aiogram/bot/api.py", line 119, in check_result
    exceptions.ConflictError.detect(description)
  File "/usr/local/lib/python3.9/site-packages/aiogram/utils/exceptions.py", line 140, in detect
    raise err(cls.text or description)
aiogram.utils.exceptions.TerminatedByOtherGetUpdates: Terminated by other getupdates request; make sure that only one bot instance is running
Cause exception while getting updates.
Traceback (most recent call last):
  File "/usr/local/lib/python3.9/site-packages/aiogram/dispatcher/dispatcher.py", line 381, in start_polling
    updates = await self.bot.get_updates(
  File "/usr/local/lib/python3.9/site-packages/aiogram/bot/bot.py", line 110, in get_updates
    result = await self.request(api.Methods.GET_UPDATES, payload)
  File "/usr/local/lib/python3.9/site-packages/aiogram/bot/base.py", line 236, in request
    return await api.make_request(await self.get_session(), self.server, self.__token, method, data, files,
  File "/usr/local/lib/python3.9/site-packages/aiogram/bot/api.py", line 140, in make_request
    return check_result(method, response.content_type, response.status, await response.text())
  File "/usr/local/lib/python3.9/site-packages/aiogram/bot/api.py", line 119, in check_result
    exceptions.ConflictError.detect(description)
  File "/usr/local/lib/python3.9/site-packages/aiogram/utils/exceptions.py", line 140, in detect
    raise err(cls.text or description)
aiogram.utils.exceptions.TerminatedByOtherGetUpdates: Terminated by other getupdates request; make sure that only one bot instance is running
Cause exception while getting updates.
Traceback (most recent call last):
  File "/usr/local/lib/python3.9/site-packages/aiogram/dispatcher/dispatcher.py", line 381, in start_polling
    updates = await self.bot.get_updates(
  File "/usr/local/lib/python3.9/site-packages/aiogram/bot/bot.py", line 110, in get_updates
    result = await self.request(api.Methods.GET_UPDATES, payload)
  File "/usr/local/lib/python3.9/site-packages/aiogram/bot/base.py", line 236, in request
    return await api.make_request(await self.get_session(), self.server, self.__token, method, data, files,
  File "/usr/local/lib/python3.9/site-packages/aiogram/bot/api.py", line 140, in make_request
    return check_result(method, response.content_type, response.status, await response.text())
  File "/usr/local/lib/python3.9/site-packages/aiogram/bot/api.py", line 119, in check_result
    exceptions.ConflictError.detect(description)
  File "/usr/local/lib/python3.9/site-packages/aiogram/utils/exceptions.py", line 140, in detect
    raise err(cls.text or description)
aiogram.utils.exceptions.TerminatedByOtherGetUpdates: Terminated by other getupdates request; make sure that only one bot instance is running
Cause exception while getting updates.
Traceback (most recent call last):
  File "/usr/local/lib/python3.9/site-packages/aiogram/dispatcher/dispatcher.py", line 381, in start_polling
    updates = await self.bot.get_updates(
  File "/usr/local/lib/python3.9/site-packages/aiogram/bot/bot.py", line 110, in get_updates
    result = await self.request(api.Methods.GET_UPDATES, payload)
  File "/usr/local/lib/python3.9/site-packages/aiogram/bot/base.py", line 236, in request
    return await api.make_request(await self.get_session(), self.server, self.__token, method, data, files,
  File "/usr/local/lib/python3.9/site-packages/aiogram/bot/api.py", line 140, in make_request
    return check_result(method, response.content_type, response.status, await response.text())
  File "/usr/local/lib/python3.9/site-packages/aiogram/bot/api.py", line 119, in check_result
    exceptions.ConflictError.detect(description)
  File "/usr/local/lib/python3.9/site-packages/aiogram/utils/exceptions.py", line 140, in detect
    raise err(cls.text or description)
aiogram.utils.exceptions.TerminatedByOtherGetUpdates: Terminated by other getupdates request; make sure that only one bot instance is running
Cause exception while getting updates.
Traceback (most recent call last):
  File "/usr/local/lib/python3.9/site-packages/aiogram/dispatcher/dispatcher.py", line 381, in start_polling
    updates = await self.bot.get_updates(
  File "/usr/local/lib/python3.9/site-packages/aiogram/bot/bot.py", line 110, in get_updates
    result = await self.request(api.Methods.GET_UPDATES, payload)
  File "/usr/local/lib/python3.9/site-packages/aiogram/bot/base.py", line 236, in request
    return await api.make_request(await self.get_session(), self.server, self.__token, method, data, files,
  File "/usr/local/lib/python3.9/site-packages/aiogram/bot/api.py", line 140, in make_request
    return check_result(method, response.content_type, response.status, await response.text())
  File "/usr/local/lib/python3.9/site-packages/aiogram/bot/api.py", line 119, in check_result
    exceptions.ConflictError.detect(description)
  File "/usr/local/lib/python3.9/site-packages/aiogram/utils/exceptions.py", line 140, in detect
    raise err(cls.text or description)
aiogram.utils.exceptions.TerminatedByOtherGetUpdates: Terminated by other getupdates request; make sure that only one bot instance is running
Cause exception while getting updates.
Traceback (most recent call last):
  File "/usr/local/lib/python3.9/site-packages/aiogram/dispatcher/dispatcher.py", line 381, in start_polling
    updates = await self.bot.get_updates(
  File "/usr/local/lib/python3.9/site-packages/aiogram/bot/bot.py", line 110, in get_updates
    result = await self.request(api.Methods.GET_UPDATES, payload)
  File "/usr/local/lib/python3.9/site-packages/aiogram/bot/base.py", line 236, in request
    return await api.make_request(await self.get_session(), self.server, self.__token, method, data, files,
  File "/usr/local/lib/python3.9/site-packages/aiogram/bot/api.py", line 140, in make_request
    return check_result(method, response.content_type, response.status, await response.text())
  File "/usr/local/lib/python3.9/site-packages/aiogram/bot/api.py", line 119, in check_result
    exceptions.ConflictError.detect(description)
  File "/usr/local/lib/python3.9/site-packages/aiogram/utils/exceptions.py", line 140, in detect
    raise err(cls.text or description)
aiogram.utils.exceptions.TerminatedByOtherGetUpdates: Terminated by other getupdates request; make sure that only one bot instance is running
kill: not enough arguments
92.43.167.54 - - [07/Aug/2023 12:58:33] "GET / HTTP/1.1" 200 -
92.43.167.54 - - [07/Aug/2023 12:58:34] "GET /static/css/main/main.css HTTP/1.1" 304 -
92.43.167.54 - - [07/Aug/2023 12:58:34] "GET /static/css/main/index.css HTTP/1.1" 304 -
92.43.167.54 - - [07/Aug/2023 12:58:34] "GET /static/img/icon_moder.svg HTTP/1.1" 304 -
92.43.167.54 - - [07/Aug/2023 12:58:34] "GET /static/img/icon_messages.svg HTTP/1.1" 304 -
92.43.167.54 - - [07/Aug/2023 12:58:34] "GET /static/img/icon_automod.svg HTTP/1.1" 304 -
92.43.167.54 - - [07/Aug/2023 12:58:34] "GET /static/img/icon_joke.svg HTTP/1.1" 304 -
92.43.167.54 - - [07/Aug/2023 12:58:34] "GET /static/img/icon_autorole.svg HTTP/1.1" 304 -
92.43.167.54 - - [07/Aug/2023 12:58:34] "GET /static/img/icon_color.svg HTTP/1.1" 304 -
92.43.167.54 - - [07/Aug/2023 12:58:34] "GET /static/img/icon_translate.svg HTTP/1.1" 304 -
92.43.167.54 - - [07/Aug/2023 12:58:34] "GET /static/img/icon_gpt.svg HTTP/1.1" 304 -
92.43.167.54 - - [07/Aug/2023 12:58:34] "GET /static/img/icon_twitch.svg HTTP/1.1" 304 -
92.43.167.54 - - [07/Aug/2023 12:58:34] "GET /static/img/icon_youtube.svg HTTP/1.1" 304 -
Cause exception while getting updates.
Traceback (most recent call last):
  File "/usr/local/lib/python3.9/site-packages/aiogram/dispatcher/dispatcher.py", line 381, in start_polling
    updates = await self.bot.get_updates(
  File "/usr/local/lib/python3.9/site-packages/aiogram/bot/bot.py", line 110, in get_updates
    result = await self.request(api.Methods.GET_UPDATES, payload)
  File "/usr/local/lib/python3.9/site-packages/aiogram/bot/base.py", line 236, in request
    return await api.make_request(await self.get_session(), self.server, self.__token, method, data, files,
  File "/usr/local/lib/python3.9/site-packages/aiogram/bot/api.py", line 140, in make_request
    return check_result(method, response.content_type, response.status, await response.text())
  File "/usr/local/lib/python3.9/site-packages/aiogram/bot/api.py", line 119, in check_result
    exceptions.ConflictError.detect(description)
  File "/usr/local/lib/python3.9/site-packages/aiogram/utils/exceptions.py", line 140, in detect
    raise err(cls.text or description)
aiogram.utils.exceptions.TerminatedByOtherGetUpdates: Terminated by other getupdates request; make sure that only one bot instance is running
Cause exception while getting updates.
Traceback (most recent call last):
  File "/usr/local/lib/python3.9/site-packages/aiogram/dispatcher/dispatcher.py", line 381, in start_polling
    updates = await self.bot.get_updates(
  File "/usr/local/lib/python3.9/site-packages/aiogram/bot/bot.py", line 110, in get_updates
    result = await self.request(api.Methods.GET_UPDATES, payload)
  File "/usr/local/lib/python3.9/site-packages/aiogram/bot/base.py", line 236, in request
    return await api.make_request(await self.get_session(), self.server, self.__token, method, data, files,
  File "/usr/local/lib/python3.9/site-packages/aiogram/bot/api.py", line 140, in make_request
    return check_result(method, response.content_type, response.status, await response.text())
  File "/usr/local/lib/python3.9/site-packages/aiogram/bot/api.py", line 119, in check_result
    exceptions.ConflictError.detect(description)
  File "/usr/local/lib/python3.9/site-packages/aiogram/utils/exceptions.py", line 140, in detect
    raise err(cls.text or description)
aiogram.utils.exceptions.TerminatedByOtherGetUpdates: Terminated by other getupdates request; make sure that only one bot instance is running
